Workbook

Sheet Dashboard
A1: Edge Lab — Inventory Dashboard
A2: Last updated: fill manually
A4: Total Item Types | B4: Total Qty in Lab | C4: Active Bins | D4: Checked Out | E4: Overdue | F4: Returned (total)
A5: =COUNTA(Inventory!A3:A302) -> 244 | B5: =SUM(Inventory!C3:C302) -> 2160 | C5: =COUNTA(Bins!A3:A262) -> 238 | D5: =COUNTIF('Checkout Log'!L3:L302,"Checked Out") -> 4 | E5: =COUNTIF('Checkout Log'!L3:L302,"Overdue") -> 0 | F5: =COUNTIF('Checkout Log'!L3:L302,"Returned") -> 0
A7: Storage Overview — by Closet
A8: Closet | B8: Type | C8: No. of Rows | D8: Bins Used | E8: Item Types | F8: Total Qty
A9: =IF(Closets!A3="","",Closets!A3) -> C1 | B9: =IF(Closets!A3="","",Closets!B3) -> PC Periphery | C9: =IF(Closets!A3="","",Closets!C3) -> 5 | D9: =IF(Closets!A3="","",COUNTIF(Bins!$B:$B,Closets!A3)) -> 18 | E9: =IF(Closets!A3="","",COUNTIF(Inventory!$E:$E,Closets!A3)) -> 15 | F9: =IF(Closets!A3="","",SUMIF(Inventory!$E:$E,Closets!A3,Inventory!$C:$C)) -> 145
A10: =IF(Closets!A4="","",Closets!A4) -> C2 | B10: =IF(Closets!A4="","",Closets!B4) -> ELE stuff | C10: =IF(Closets!A4="","",Closets!C4) -> 5 | D10: =IF(Closets!A4="","",COUNTIF(Bins!$B:$B,Closets!A4)) -> 20 | E10: =IF(Closets!A4="","",COUNTIF(Inventory!$E:$E,Closets!A4)) -> 20 | F10: =IF(Closets!A4="","",SUMIF(Inventory!$E:$E,Closets!A4,Inventory!$C:$C)) -> 150
A11: =IF(Closets!A5="","",Closets!A5) -> C3 | B11: =IF(Closets!A5="","",Closets!B5) -> ELE stuff | C11: =IF(Closets!A5="","",Closets!C5) -> 9 | D11: =IF(Closets!A5="","",COUNTIF(Bins!$B:$B,Closets!A5)) -> 94 | E11: =IF(Closets!A5="","",COUNTIF(Inventory!$E:$E,Closets!A5)) -> 139 | F11: =IF(Closets!A5="","",SUMIF(Inventory!$E:$E,Closets!A5,Inventory!$C:$C)) -> 1283
A12: =IF(Closets!A6="","",Closets!A6) -> C4 | B12: =IF(Closets!A6="","",Closets!B6) -> Tools | C12: =IF(Closets!A6="","",Closets!C6) -> 5 | D12: =IF(Closets!A6="","",COUNTIF(Bins!$B:$B,Closets!A6)) -> 14 | E12: =IF(Closets!A6="","",COUNTIF(Inventory!$E:$E,Closets!A6)) -> 3 | F12: =IF(Closets!A6="","",SUMIF(Inventory!$E:$E,Closets!A6,Inventory!$C:$C)) -> 18
A13: =IF(Closets!A7="","",Closets!A7) -> C5 | B13: =IF(Closets!A7="","",Closets!B7) -> Projects | C13: =IF(Closets!A7="","",Closets!C7) -> 4 | D13: =IF(Closets!A7="","",COUNTIF(Bins!$B:$B,Closets!A7)) -> 12 | E13: =IF(Closets!A7="","",COUNTIF(Inventory!$E:$E,Closets!A7)) -> 1 | F13: =IF(Closets!A7="","",SUMIF(Inventory!$E:$E,Closets!A7,Inventory!$C:$C)) -> 4
A14: =IF(Closets!A8="","",Closets!A8) -> C6 | B14: =IF(Closets!A8="","",Closets!B8) -> Misc | C14: =IF(Closets!A8="","",Closets!C8) -> 4 | D14: =IF(Closets!A8="","",COUNTIF(Bins!$B:$B,Closets!A8)) -> 8 | E14: =IF(Closets!A8="","",COUNTIF(Inventory!$E:$E,Closets!A8)) -> 3 | F14: =IF(Closets!A8="","",SUMIF(Inventory!$E:$E,Closets!A8,Inventory!$C:$C)) -> 58
A15: =IF(Closets!A9="","",Closets!A9) -> C7 | B15: =IF(Closets!A9="","",Closets!B9) -> Boxes | C15: =IF(Closets!A9="","",Closets!C9) -> 5 | D15: =IF(Closets!A9="","",COUNTIF(Bins!$B:$B,Closets!A9)) -> 7 | E15: =IF(Closets!A9="","",COUNTIF(Inventory!$E:$E,Closets!A9)) -> 3 | F15: =IF(Closets!A9="","",SUMIF(Inventory!$E:$E,Closets!A9,Inventory!$C:$C)) -> 50
A16: =IF(Closets!A10="","",Closets!A10) -> SCC1 | B16: =IF(Closets!A10="","",Closets!B10) -> ELE stuff | C16: =IF(Closets!A10="","",Closets!C10) -> 5 | D16: =IF(Closets!A10="","",COUNTIF(Bins!$B:$B,Closets!A10)) -> 0 | E16: =IF(Closets!A10="","",COUNTIF(Inventory!$E:$E,Closets!A10)) -> 0 | F16: =IF(Closets!A10="","",SUMIF(Inventory!$E:$E,Closets!A10,Inventory!$C:$C)) -> 0
A17: =IF(Closets!A11="","",Closets!A11) -> SCC2 | B17: =IF(Closets!A11="","",Closets!B11) -> Tools | C17: =IF(Closets!A11="","",Closets!C11) -> 5 | D17: =IF(Closets!A11="","",COUNTIF(Bins!$B:$B,Closets!A11)) -> 0 | E17: =IF(Closets!A11="","",COUNTIF(Inventory!$E:$E,Closets!A11)) -> 0 | F17: =IF(Closets!A11="","",SUMIF(Inventory!$E:$E,Closets!A11,Inventory!$C:$C)) -> 0
A18: =IF(Closets!A12="","",Closets!A12) -> SCC3 | B18: =IF(Closets!A12="","",Closets!B12) -> Tools | C18: =IF(Closets!A12="","",Closets!C12) -> 5 | D18: =IF(Closets!A12="","",COUNTIF(Bins!$B:$B,Closets!A12)) -> 0 | E18: =IF(Closets!A12="","",COUNTIF(Inventory!$E:$E,Closets!A12)) -> 0 | F18: =IF(Closets!A12="","",SUMIF(Inventory!$E:$E,Closets!A12,Inventory!$C:$C)) -> 0
A19: =IF(Closets!A13="","",Closets!A13) -> SCC4 | B19: =IF(Closets!A13="","",Closets!B13) -> Projects | C19: =IF(Closets!A13="","",Closets!C13) -> 5 | D19: =IF(Closets!A13="","",COUNTIF(Bins!$B:$B,Closets!A13)) -> 0 | E19: =IF(Closets!A13="","",COUNTIF(Inventory!$E:$E,Closets!A13)) -> 0 | F19: =IF(Closets!A13="","",SUMIF(Inventory!$E:$E,Closets!A13,Inventory!$C:$C)) -> 0
A20: =IF(Closets!A14="","",Closets!A14) -> SL5 | B20: =IF(Closets!A14="","",Closets!B14) -> Misc | C20: =IF(Closets!A14="","",Closets!C14) -> 4 | D20: =IF(Closets!A14="","",COUNTIF(Bins!$B:$B,Closets!A14)) -> 8 | E20: =IF(Closets!A14="","",COUNTIF(Inventory!$E:$E,Closets!A14)) -> 1 | F20: =IF(Closets!A14="","",SUMIF(Inventory!$E:$E,Closets!A14,Inventory!$C:$C)) -> 18
... A28: =IF(Closets!A22="","",Closets!A22) | B28: =IF(Closets!A22="","",Closets!B22) | C28: =IF(Closets!A22="","",Closets!C22) | D28: =IF(Closets!A22="","",COUNTIF(Bins!$B:$B,Closets!A22)) | E28: =IF(Closets!A22="","",COUNTIF(Inventory!$E:$E,Closets!A22)) | F28: =IF(Closets!A22="","",SUMIF(Inventory!$E:$E,Closets!A22,Inventory!$C:$C))
A30: Active Checkouts
A31: Item Name | B31: Bin | C31: Closet | D31: Borrower | E31: Checkout Date | F31: Expected Return
A32: =IFERROR(IF(INDEX('Checkout Log'!$A:$A,SMALL($G$32:$G$232,ROW()-ROW($G$32)+1))="","",INDEX('Checkout Log'!$A:$A,SMALL($G$32:$G$232,ROW()-ROW($G$32)+1))),"") -> STM32F756 Nucleo-144 Microcontroller | B32: =IFERROR(IF(INDEX('Checkout Log'!$C:$C,SMALL($G$32:$G$232,ROW()-ROW($G$32)+1))="","",INDEX('Checkout Log'!$C:$C,SMALL($G$32:$G$232,ROW()-ROW($G$32)+1))),"") -> STM 32 Microcontrollers | C32: =IFERROR(IF(INDEX('Checkout Log'!$D:$D,SMALL($G$32:$G$232,ROW()-ROW($G$32)+1))="","",INDEX('Checkout Log'!$D:$D,SMALL($G$32:$G$232,ROW()-ROW($G$32)+1))),"") -> C2 | D32: Narmada borrowed 2 | E32: =IFERROR(IF(INDEX('Checkout Log'!$H:$H,SMALL($G$32:$G$232,ROW()-ROW($G$32)+1))=0,"",INDEX('Checkout Log'!$H:$H,SMALL($G$32:$G$232,ROW()-ROW($G$32)+1))),"") | F32: =IFERROR(IF(INDEX('Checkout Log'!$I:$I,SMALL($G$32:$G$232,ROW()-ROW($G$32)+1))=0,"",INDEX('Checkout Log'!$I:$I,SMALL($G$32:$G$232,ROW()-ROW($G$32)+1))),"") | G32: =IF('Checkout Log'!$A3="","",IF('Checkout Log'!$L3="Returned","",ROW('Checkout Log'!$A3))) -> 3
A33: =IFERROR(IF(INDEX('Checkout Log'!$A:$A,SMALL($G$32:$G$232,ROW()-ROW($G$32)+1))="","",INDEX('Checkout Log'!$A:$A,SMALL($G$32:$G$232,ROW()-ROW($G$32)+1))),"") -> STM32MP157C-DK2 Microcontroller | B33: =IFERROR(IF(INDEX('Checkout Log'!$C:$C,SMALL($G$32:$G$232,ROW()-ROW($G$32)+1))="","",INDEX('Checkout Log'!$C:$C,SMALL($G$32:$G$232,ROW()-ROW($G$32)+1))),"") -> STM 32 Microcontrollers | C33: =IFERROR(IF(INDEX('Checkout Log'!$D:$D,SMALL($G$32:$G$232,ROW()-ROW($G$32)+1))="","",INDEX('Checkout Log'!$D:$D,SMALL($G$32:$G$232,ROW()-ROW($G$32)+1))),"") -> C2 | D33: Shehan borrowed 2 | E33: =IFERROR(IF(INDEX('Checkout Log'!$H:$H,SMALL($G$32:$G$232,ROW()-ROW($G$32)+1))=0,"",INDEX('Checkout Log'!$H:$H,SMALL($G$32:$G$232,ROW()-ROW($G$32)+1))),"") | F33: =IFERROR(IF(INDEX('Checkout Log'!$I:$I,SMALL($G$32:$G$232,ROW()-ROW($G$32)+1))=0,"",INDEX('Checkout Log'!$I:$I,SMALL($G$32:$G$232,ROW()-ROW($G$32)+1))),"") | G33: =IF('Checkout Log'!$A4="","",IF('Checkout Log'!$L4="Returned","",ROW('Checkout Log'!$A4))) -> 4
A34: =IFERROR(IF(INDEX('Checkout Log'!$A:$A,SMALL($G$32:$G$232,ROW()-ROW($G$32)+1))="","",INDEX('Checkout Log'!$A:$A,SMALL($G$32:$G$232,ROW()-ROW($G$32)+1))),"") -> BitCraze CrazyFlie drone kit | B34: =IFERROR(IF(INDEX('Checkout Log'!$C:$C,SMALL($G$32:$G$232,ROW()-ROW($G$32)+1))="","",INDEX('Checkout Log'!$C:$C,SMALL($G$32:$G$232,ROW()-ROW($G$32)+1))),"") -> BitCraze CrazyFlie drone kit | C34: =IFERROR(IF(INDEX('Checkout Log'!$D:$D,SMALL($G$32:$G$232,ROW()-ROW($G$32)+1))="","",INDEX('Checkout Log'!$D:$D,SMALL($G$32:$G$232,ROW()-ROW($G$32)+1))),"") -> SL2 | D34: Domenic Dreschel borrowed 1 | E34: =IFERROR(IF(INDEX('Checkout Log'!$H:$H,SMALL($G$32:$G$232,ROW()-ROW($G$32)+1))=0,"",INDEX('Checkout Log'!$H:$H,SMALL($G$32:$G$232,ROW()-ROW($G$32)+1))),"") | F34: =IFERROR(IF(INDEX('Checkout Log'!$I:$I,SMALL($G$32:$G$232,ROW()-ROW($G$32)+1))=0,"",INDEX('Checkout Log'!$I:$I,SMALL($G$32:$G$232,ROW()-ROW($G$32)+1))),"") | G34: =IF('Checkout Log'!$A5="","",IF('Checkout Log'!$L5="Returned","",ROW('Checkout Log'!$A5))) -> 5
A35: =IFERROR(IF(INDEX('Checkout Log'!$A:$A,SMALL($G$32:$G$232,ROW()-ROW($G$32)+1))="","",INDEX('Checkout Log'!$A:$A,SMALL($G$32:$G$232,ROW()-ROW($G$32)+1))),"") -> Servo Motor S35+XF | B35: =IFERROR(IF(INDEX('Checkout Log'!$C:$C,SMALL($G$32:$G$232,ROW()-ROW($G$32)+1))="","",INDEX('Checkout Log'!$C:$C,SMALL($G$32:$G$232,ROW()-ROW($G$32)+1))),"") -> Servo Motors | C35: =IFERROR(IF(INDEX('Checkout Log'!$D:$D,SMALL($G$32:$G$232,ROW()-ROW($G$32)+1))="","",INDEX('Checkout Log'!$D:$D,SMALL($G$32:$G$232,ROW()-ROW($G$32)+1))),"") -> C3 | D35: =IFERROR(IF(INDEX('Checkout Log'!$E:$E,SMALL($G$32:$G$232,ROW()-ROW($G$32)+1))="","",INDEX('Checkout Log'!$E:$E,SMALL($G$32:$G$232,ROW()-ROW($G$32)+1))),"") -> MD Akram | E35: =IFERROR(IF(INDEX('Checkout Log'!$H:$H,SMALL($G$32:$G$232,ROW()-ROW($G$32)+1))=0,"",INDEX('Checkout Log'!$H:$H,SMALL($G$32:$G$232,ROW()-ROW($G$32)+1))),"") | F35: =IFERROR(IF(INDEX('Checkout Log'!$I:$I,SMALL($G$32:$G$232,ROW()-ROW($G$32)+1))=0,"",INDEX('Checkout Log'!$I:$I,SMALL($G$32:$G$232,ROW()-ROW($G$32)+1))),"") | G35: =IF('Checkout Log'!$A6="","",IF('Checkout Log'!$L6="Returned","",ROW('Checkout Log'!$A6))) -> 6
A36: =IFERROR(IF(INDEX('Checkout Log'!$A:$A,SMALL($G$32:$G$232,ROW()-ROW($G$32)+1))="","",INDEX('Checkout Log'!$A:$A,SMALL($G$32:$G$232,ROW()-ROW($G$32)+1))),"") | B36: =IFERROR(IF(INDEX('Checkout Log'!$C:$C,SMALL($G$32:$G$232,ROW()-ROW($G$32)+1))="","",INDEX('Checkout Log'!$C:$C,SMALL($G$32:$G$232,ROW()-ROW($G$32)+1))),"") | C36: =IFERROR(IF(INDEX('Checkout Log'!$D:$D,SMALL($G$32:$G$232,ROW()-ROW($G$32)+1))="","",INDEX('Checkout Log'!$D:$D,SMALL($G$32:$G$232,ROW()-ROW($G$32)+1))),"") | D36: =IFERROR(IF(INDEX('Checkout Log'!$E:$E,SMALL($G$32:$G$232,ROW()-ROW($G$32)+1))="","",INDEX('Checkout Log'!$E:$E,SMALL($G$32:$G$232,ROW()-ROW($G$32)+1))),"") | E36: =IFERROR(IF(INDEX('Checkout Log'!$H:$H,SMALL($G$32:$G$232,ROW()-ROW($G$32)+1))=0,"",INDEX('Checkout Log'!$H:$H,SMALL($G$32:$G$232,ROW()-ROW($G$32)+1))),"") | F36: =IFERROR(IF(INDEX('Checkout Log'!$I:$I,SMALL($G$32:$G$232,ROW()-ROW($G$32)+1))=0,"",INDEX('Checkout Log'!$I:$I,SMALL($G$32:$G$232,ROW()-ROW($G$32)+1))),"") | G36: =IF('Checkout Log'!$A7="","",IF('Checkout Log'!$L7="Returned","",ROW('Checkout Log'!$A7)))
A37: =IFERROR(IF(INDEX('Checkout Log'!$A:$A,SMALL($G$32:$G$232,ROW()-ROW($G$32)+1))="","",INDEX('Checkout Log'!$A:$A,SMALL($G$32:$G$232,ROW()-ROW($G$32)+1))),"") | B37: =IFERROR(IF(INDEX('Checkout Log'!$C:$C,SMALL($G$32:$G$232,ROW()-ROW($G$32)+1))="","",INDEX('Checkout Log'!$C:$C,SMALL($G$32:$G$232,ROW()-ROW($G$32)+1))),"") | C37: =IFERROR(IF(INDEX('Checkout Log'!$D:$D,SMALL($G$32:$G$232,ROW()-ROW($G$32)+1))="","",INDEX('Checkout Log'!$D:$D,SMALL($G$32:$G$232,ROW()-ROW($G$32)+1))),"") | D37: =IFERROR(IF(INDEX('Checkout Log'!$E:$E,SMALL($G$32:$G$232,ROW()-ROW($G$32)+1))="","",INDEX('Checkout Log'!$E:$E,SMALL($G$32:$G$232,ROW()-ROW($G$32)+1))),"") | E37: =IFERROR(IF(INDEX('Checkout Log'!$H:$H,SMALL($G$32:$G$232,ROW()-ROW($G$32)+1))=0,"",INDEX('Checkout Log'!$H:$H,SMALL($G$32:$G$232,ROW()-ROW($G$32)+1))),"") | F37: =IFERROR(IF(INDEX('Checkout Log'!$I:$I,SMALL($G$32:$G$232,ROW()-ROW($G$32)+1))=0,"",INDEX('Checkout Log'!$I:$I,SMALL($G$32:$G$232,ROW()-ROW($G$32)+1))),"") | G37: =IF('Checkout Log'!$A8="","",IF('Checkout Log'!$L8="Returned","",ROW('Checkout Log'!$A8)))
A38: =IFERROR(IF(INDEX('Checkout Log'!$A:$A,SMALL($G$32:$G$232,ROW()-ROW($G$32)+1))="","",INDEX('Checkout Log'!$A:$A,SMALL($G$32:$G$232,ROW()-ROW($G$32)+1))),"") | B38: =IFERROR(IF(INDEX('Checkout Log'!$C:$C,SMALL($G$32:$G$232,ROW()-ROW($G$32)+1))="","",INDEX('Checkout Log'!$C:$C,SMALL($G$32:$G$232,ROW()-ROW($G$32)+1))),"") | C38: =IFERROR(IF(INDEX('Checkout Log'!$D:$D,SMALL($G$32:$G$232,ROW()-ROW($G$32)+1))="","",INDEX('Checkout Log'!$D:$D,SMALL($G$32:$G$232,ROW()-ROW($G$32)+1))),"") | D38: =IFERROR(IF(INDEX('Checkout Log'!$E:$E,SMALL($G$32:$G$232,ROW()-ROW($G$32)+1))="","",INDEX('Checkout Log'!$E:$E,SMALL($G$32:$G$232,ROW()-ROW($G$32)+1))),"") | E38: =IFERROR(IF(INDEX('Checkout Log'!$H:$H,SMALL($G$32:$G$232,ROW()-ROW($G$32)+1))=0,"",INDEX('Checkout Log'!$H:$H,SMALL($G$32:$G$232,ROW()-ROW($G$32)+1))),"") | F38: =IFERROR(IF(INDEX('Checkout Log'!$I:$I,SMALL($G$32:$G$232,ROW()-ROW($G$32)+1))=0,"",INDEX('Checkout Log'!$I:$I,SMALL($G$32:$G$232,ROW()-ROW($G$32)+1))),"") | G38: =IF('Checkout Log'!$A9="","",IF('Checkout Log'!$L9="Returned","",ROW('Checkout Log'!$A9)))
A39: =IFERROR(IF(INDEX('Checkout Log'!$A:$A,SMALL($G$32:$G$232,ROW()-ROW($G$32)+1))="","",INDEX('Checkout Log'!$A:$A,SMALL($G$32:$G$232,ROW()-ROW($G$32)+1))),"") | B39: =IFERROR(IF(INDEX('Checkout Log'!$C:$C,SMALL($G$32:$G$232,ROW()-ROW($G$32)+1))="","",INDEX('Checkout Log'!$C:$C,SMALL($G$32:$G$232,ROW()-ROW($G$32)+1))),"") | C39: =IFERROR(IF(INDEX('Checkout Log'!$D:$D,SMALL($G$32:$G$232,ROW()-ROW($G$32)+1))="","",INDEX('Checkout Log'!$D:$D,SMALL($G$32:$G$232,ROW()-ROW($G$32)+1))),"") | D39: =IFERROR(IF(INDEX('Checkout Log'!$E:$E,SMALL($G$32:$G$232,ROW()-ROW($G$32)+1))="","",INDEX('Checkout Log'!$E:$E,SMALL($G$32:$G$232,ROW()-ROW($G$32)+1))),"") | E39: =IFERROR(IF(INDEX('Checkout Log'!$H:$H,SMALL($G$32:$G$232,ROW()-ROW($G$32)+1))=0,"",INDEX('Checkout Log'!$H:$H,SMALL($G$32:$G$232,ROW()-ROW($G$32)+1))),"") | F39: =IFERROR(IF(INDEX('Checkout Log'!$I:$I,SMALL($G$32:$G$232,ROW()-ROW($G$32)+1))=0,"",INDEX('Checkout Log'!$I:$I,SMALL($G$32:$G$232,ROW()-ROW($G$32)+1))),"") | G39: =IF('Checkout Log'!$A10="","",IF('Checkout Log'!$L10="Returned","",ROW('Checkout Log'!$A10)))
A40: =IFERROR(IF(INDEX('Checkout Log'!$A:$A,SMALL($G$32:$G$232,ROW()-ROW($G$32)+1))="","",INDEX('Checkout Log'!$A:$A,SMALL($G$32:$G$232,ROW()-ROW($G$32)+1))),"") | B40: =IFERROR(IF(INDEX('Checkout Log'!$C:$C,SMALL($G$32:$G$232,ROW()-ROW($G$32)+1))="","",INDEX('Checkout Log'!$C:$C,SMALL($G$32:$G$232,ROW()-ROW($G$32)+1))),"") | C40: =IFERROR(IF(INDEX('Checkout Log'!$D:$D,SMALL($G$32:$G$232,ROW()-ROW($G$32)+1))="","",INDEX('Checkout Log'!$D:$D,SMALL($G$32:$G$232,ROW()-ROW($G$32)+1))),"") | D40: =IFERROR(IF(INDEX('Checkout Log'!$E:$E,SMALL($G$32:$G$232,ROW()-ROW($G$32)+1))="","",INDEX('Checkout Log'!$E:$E,SMALL($G$32:$G$232,ROW()-ROW($G$32)+1))),"") | E40: =IFERROR(IF(INDEX('Checkout Log'!$H:$H,SMALL($G$32:$G$232,ROW()-ROW($G$32)+1))=0,"",INDEX('Checkout Log'!$H:$H,SMALL($G$32:$G$232,ROW()-ROW($G$32)+1))),"") | F40: =IFERROR(IF(INDEX('Checkout Log'!$I:$I,SMALL($G$32:$G$232,ROW()-ROW($G$32)+1))=0,"",INDEX('Checkout Log'!$I:$I,SMALL($G$32:$G$232,ROW()-ROW($G$32)+1))),"") | G40: =IF('Checkout Log'!$A11="","",IF('Checkout Log'!$L11="Returned","",ROW('Checkout Log'!$A11)))
A41: =IFERROR(IF(INDEX('Checkout Log'!$A:$A,SMALL($G$32:$G$232,ROW()-ROW($G$32)+1))="","",INDEX('Checkout Log'!$A:$A,SMALL($G$32:$G$232,ROW()-ROW($G$32)+1))),"") | B41: =IFERROR(IF(INDEX('Checkout Log'!$C:$C,SMALL($G$32:$G$232,ROW()-ROW($G$32)+1))="","",INDEX('Checkout Log'!$C:$C,SMALL($G$32:$G$232,ROW()-ROW($G$32)+1))),"") | C41: =IFERROR(IF(INDEX('Checkout Log'!$D:$D,SMALL($G$32:$G$232,ROW()-ROW($G$32)+1))="","",INDEX('Checkout Log'!$D:$D,SMALL($G$32:$G$232,ROW()-ROW($G$32)+1))),"") | D41: =IFERROR(IF(INDEX('Checkout Log'!$E:$E,SMALL($G$32:$G$232,ROW()-ROW($G$32)+1))="","",INDEX('Checkout Log'!$E:$E,SMALL($G$32:$G$232,ROW()-ROW($G$32)+1))),"") | E41: =IFERROR(IF(INDEX('Checkout Log'!$H:$H,SMALL($G$32:$G$232,ROW()-ROW($G$32)+1))=0,"",INDEX('Checkout Log'!$H:$H,SMALL($G$32:$G$232,ROW()-ROW($G$32)+1))),"") | F41: =IFERROR(IF(INDEX('Checkout Log'!$I:$I,SMALL($G$32:$G$232,ROW()-ROW($G$32)+1))=0,"",INDEX('Checkout Log'!$I:$I,SMALL($G$32:$G$232,ROW()-ROW($G$32)+1))),"") | G41: =IF('Checkout Log'!$A12="","",IF('Checkout Log'!$L12="Returned","",ROW('Checkout Log'!$A12)))
A42: =IFERROR(IF(INDEX('Checkout Log'!$A:$A,SMALL($G$32:$G$232,ROW()-ROW($G$32)+1))="","",INDEX('Checkout Log'!$A:$A,SMALL($G$32:$G$232,ROW()-ROW($G$32)+1))),"") | B42: =IFERROR(IF(INDEX('Checkout Log'!$C:$C,SMALL($G$32:$G$232,ROW()-ROW($G$32)+1))="","",INDEX('Checkout Log'!$C:$C,SMALL($G$32:$G$232,ROW()-ROW($G$32)+1))),"") | C42: =IFERROR(IF(INDEX('Checkout Log'!$D:$D,SMALL($G$32:$G$232,ROW()-ROW($G$32)+1))="","",INDEX('Checkout Log'!$D:$D,SMALL($G$32:$G$232,ROW()-ROW($G$32)+1))),"") | D42: =IFERROR(IF(INDEX('Checkout Log'!$E:$E,SMALL($G$32:$G$232,ROW()-ROW($G$32)+1))="","",INDEX('Checkout Log'!$E:$E,SMALL($G$32:$G$232,ROW()-ROW($G$32)+1))),"") | E42: =IFERROR(IF(INDEX('Checkout Log'!$H:$H,SMALL($G$32:$G$232,ROW()-ROW($G$32)+1))=0,"",INDEX('Checkout Log'!$H:$H,SMALL($G$32:$G$232,ROW()-ROW($G$32)+1))),"") | F42: =IFERROR(IF(INDEX('Checkout Log'!$I:$I,SMALL($G$32:$G$232,ROW()-ROW($G$32)+1))=0,"",INDEX('Checkout Log'!$I:$I,SMALL($G$32:$G$232,ROW()-ROW($G$32)+1))),"") | G42: =IF('Checkout Log'!$A13="","",IF('Checkout Log'!$L13="Returned","",ROW('Checkout Log'!$A13)))
A43: =IFERROR(IF(INDEX('Checkout Log'!$A:$A,SMALL($G$32:$G$232,ROW()-ROW($G$32)+1))="","",INDEX('Checkout Log'!$A:$A,SMALL($G$32:$G$232,ROW()-ROW($G$32)+1))),"") | B43: =IFERROR(IF(INDEX('Checkout Log'!$C:$C,SMALL($G$32:$G$232,ROW()-ROW($G$32)+1))="","",INDEX('Checkout Log'!$C:$C,SMALL($G$32:$G$232,ROW()-ROW($G$32)+1))),"") | C43: =IFERROR(IF(INDEX('Checkout Log'!$D:$D,SMALL($G$32:$G$232,ROW()-ROW($G$32)+1))="","",INDEX('Checkout Log'!$D:$D,SMALL($G$32:$G$232,ROW()-ROW($G$32)+1))),"") | D43: =IFERROR(IF(INDEX('Checkout Log'!$E:$E,SMALL($G$32:$G$232,ROW()-ROW($G$32)+1))="","",INDEX('Checkout Log'!$E:$E,SMALL($G$32:$G$232,ROW()-ROW($G$32)+1))),"") | E43: =IFERROR(IF(INDEX('Checkout Log'!$H:$H,SMALL($G$32:$G$232,ROW()-ROW($G$32)+1))=0,"",INDEX('Checkout Log'!$H:$H,SMALL($G$32:$G$232,ROW()-ROW($G$32)+1))),"") | F43: =IFERROR(IF(INDEX('Checkout Log'!$I:$I,SMALL($G$32:$G$232,ROW()-ROW($G$32)+1))=0,"",INDEX('Checkout Log'!$I:$I,SMALL($G$32:$G$232,ROW()-ROW($G$32)+1))),"") | G43: =IF('Checkout Log'!$A14="","",IF('Checkout Log'!$L14="Returned","",ROW('Checkout Log'!$A14)))
A44: =IFERROR(IF(INDEX('Checkout Log'!$A:$A,SMALL($G$32:$G$232,ROW()-ROW($G$32)+1))="","",INDEX('Checkout Log'!$A:$A,SMALL($G$32:$G$232,ROW()-ROW($G$32)+1))),"") | B44: =IFERROR(IF(INDEX('Checkout Log'!$C:$C,SMALL($G$32:$G$232,ROW()-ROW($G$32)+1))="","",INDEX('Checkout Log'!$C:$C,SMALL($G$32:$G$232,ROW()-ROW($G$32)+1))),"") | C44: =IFERROR(IF(INDEX('Checkout Log'!$D:$D,SMALL($G$32:$G$232,ROW()-ROW($G$32)+1))="","",INDEX('Checkout Log'!$D:$D,SMALL($G$32:$G$232,ROW()-ROW($G$32)+1))),"") | D44: =IFERROR(IF(INDEX('Checkout Log'!$E:$E,SMALL($G$32:$G$232,ROW()-ROW($G$32)+1))="","",INDEX('Checkout Log'!$E:$E,SMALL($G$32:$G$232,ROW()-ROW($G$32)+1))),"") | E44: =IFERROR(IF(INDEX('Checkout Log'!$H:$H,SMALL($G$32:$G$232,ROW()-ROW($G$32)+1))=0,"",INDEX('Checkout Log'!$H:$H,SMALL($G$32:$G$232,ROW()-ROW($G$32)+1))),"") | F44: =IFERROR(IF(INDEX('Checkout Log'!$I:$I,SMALL($G$32:$G$232,ROW()-ROW($G$32)+1))=0,"",INDEX('Checkout Log'!$I:$I,SMALL($G$32:$G$232,ROW()-ROW($G$32)+1))),"") | G44: =IF('Checkout Log'!$A15="","",IF('Checkout Log'!$L15="Returned","",ROW('Checkout Log'!$A15)))
A45: =IFERROR(IF(INDEX('Checkout Log'!$A:$A,SMALL($G$32:$G$232,ROW()-ROW($G$32)+1))="","",INDEX('Checkout Log'!$A:$A,SMALL($G$32:$G$232,ROW()-ROW($G$32)+1))),"") | B45: =IFERROR(IF(INDEX('Checkout Log'!$C:$C,SMALL($G$32:$G$232,ROW()-ROW($G$32)+1))="","",INDEX('Checkout Log'!$C:$C,SMALL($G$32:$G$232,ROW()-ROW($G$32)+1))),"") | C45: =IFERROR(IF(INDEX('Checkout Log'!$D:$D,SMALL($G$32:$G$232,ROW()-ROW($G$32)+1))="","",INDEX('Checkout Log'!$D:$D,SMALL($G$32:$G$232,ROW()-ROW($G$32)+1))),"") | D45: =IFERROR(IF(INDEX('Checkout Log'!$E:$E,SMALL($G$32:$G$232,ROW()-ROW($G$32)+1))="","",INDEX('Checkout Log'!$E:$E,SMALL($G$32:$G$232,ROW()-ROW($G$32)+1))),"") | E45: =IFERROR(IF(INDEX('Checkout Log'!$H:$H,SMALL($G$32:$G$232,ROW()-ROW($G$32)+1))=0,"",INDEX('Checkout Log'!$H:$H,SMALL($G$32:$G$232,ROW()-ROW($G$32)+1))),"") | F45: =IFERROR(IF(INDEX('Checkout Log'!$I:$I,SMALL($G$32:$G$232,ROW()-ROW($G$32)+1))=0,"",INDEX('Checkout Log'!$I:$I,SMALL($G$32:$G$232,ROW()-ROW($G$32)+1))),"") | G45: =IF('Checkout Log'!$A16="","",IF('Checkout Log'!$L16="Returned","",ROW('Checkout Log'!$A16)))
A46: =IFERROR(IF(INDEX('Checkout Log'!$A:$A,SMALL($G$32:$G$232,ROW()-ROW($G$32)+1))="","",INDEX('Checkout Log'!$A:$A,SMALL($G$32:$G$232,ROW()-ROW($G$32)+1))),"") | B46: =IFERROR(IF(INDEX('Checkout Log'!$C:$C,SMALL($G$32:$G$232,ROW()-ROW($G$32)+1))="","",INDEX('Checkout Log'!$C:$C,SMALL($G$32:$G$232,ROW()-ROW($G$32)+1))),"") | C46: =IFERROR(IF(INDEX('Checkout Log'!$D:$D,SMALL($G$32:$G$232,ROW()-ROW($G$32)+1))="","",INDEX('Checkout Log'!$D:$D,SMALL($G$32:$G$232,ROW()-ROW($G$32)+1))),"") | D46: =IFERROR(IF(INDEX('Checkout Log'!$E:$E,SMALL($G$32:$G$232,ROW()-ROW($G$32)+1))="","",INDEX('Checkout Log'!$E:$E,SMALL($G$32:$G$232,ROW()-ROW($G$32)+1))),"") | E46: =IFERROR(IF(INDEX('Checkout Log'!$H:$H,SMALL($G$32:$G$232,ROW()-ROW($G$32)+1))=0,"",INDEX('Checkout Log'!$H:$H,SMALL($G$32:$G$232,ROW()-ROW($G$32)+1))),"") | F46: =IFERROR(IF(INDEX('Checkout Log'!$I:$I,SMALL($G$32:$G$232,ROW()-ROW($G$32)+1))=0,"",INDEX('Checkout Log'!$I:$I,SMALL($G$32:$G$232,ROW()-ROW($G$32)+1))),"") | G46: =IF('Checkout Log'!$A17="","",IF('Checkout Log'!$L17="Returned","",ROW('Checkout Log'!$A17)))
... A100: =IFERROR(IF(INDEX('Checkout Log'!$A:$A,SMALL($G$32:$G$232,ROW()-ROW($G$32)+1))="","",INDEX('Checkout Log'!$A:$A,SMALL($G$32:$G$232,ROW()-ROW($G$32)+1))),"") | B100: =IFERROR(IF(INDEX('Checkout Log'!$C:$C,SMALL($G$32:$G$232,ROW()-ROW($G$32)+1))="","",INDEX('Checkout Log'!$C:$C,SMALL($G$32:$G$232,ROW()-ROW($G$32)+1))),"") | C100: =IFERROR(IF(INDEX('Checkout Log'!$D:$D,SMALL($G$32:$G$232,ROW()-ROW($G$32)+1))="","",INDEX('Checkout Log'!$D:$D,SMALL($G$32:$G$232,ROW()-ROW($G$32)+1))),"") | D100: =IFERROR(IF(INDEX('Checkout Log'!$E:$E,SMALL($G$32:$G$232,ROW()-ROW($G$32)+1))="","",INDEX('Checkout Log'!$E:$E,SMALL($G$32:$G$232,ROW()-ROW($G$32)+1))),"") | E100: =IFERROR(IF(INDEX('Checkout Log'!$H:$H,SMALL($G$32:$G$232,ROW()-ROW($G$32)+1))=0,"",INDEX('Checkout Log'!$H:$H,SMALL($G$32:$G$232,ROW()-ROW($G$32)+1))),"") | F100: =IFERROR(IF(INDEX('Checkout Log'!$I:$I,SMALL($G$32:$G$232,ROW()-ROW($G$32)+1))=0,"",INDEX('Checkout Log'!$I:$I,SMALL($G$32:$G$232,ROW()-ROW($G$32)+1))),"") | G100: =IF('Checkout Log'!$A71="","",IF('Checkout Log'!$L71="Returned","",ROW('Checkout Log'!$A71)))
A101: =IF('Checkout Log'!$L72<>"Checked Out","",'Checkout Log'!$A72) | B101: =IF('Checkout Log'!L72<>"Checked Out","",'Checkout Log'!C72) | C101: =IF('Checkout Log'!L72<>"Checked Out","",'Checkout Log'!D72) | D101: =IF('Checkout Log'!L72<>"Checked Out","",'Checkout Log'!E72) | E101: =IF('Checkout Log'!L72<>"Checked Out","",'Checkout Log'!H72) | F101: =IF('Checkout Log'!L72<>"Checked Out","",'Checkout Log'!I72)
A102: =IF('Checkout Log'!$L73<>"Checked Out","",'Checkout Log'!$A73) | B102: =IF('Checkout Log'!L73<>"Checked Out","",'Checkout Log'!C73) | C102: =IF('Checkout Log'!L73<>"Checked Out","",'Checkout Log'!D73) | D102: =IF('Checkout Log'!L73<>"Checked Out","",'Checkout Log'!E73) | E102: =IF('Checkout Log'!L73<>"Checked Out","",'Checkout Log'!H73) | F102: =IF('Checkout Log'!L73<>"Checked Out","",'Checkout Log'!I73)
A103: =IF('Checkout Log'!$L74<>"Checked Out","",'Checkout Log'!$A74) | B103: =IF('Checkout Log'!L74<>"Checked Out","",'Checkout Log'!C74) | C103: =IF('Checkout Log'!L74<>"Checked Out","",'Checkout Log'!D74) | D103: =IF('Checkout Log'!L74<>"Checked Out","",'Checkout Log'!E74) | E103: =IF('Checkout Log'!L74<>"Checked Out","",'Checkout Log'!H74) | F103: =IF('Checkout Log'!L74<>"Checked Out","",'Checkout Log'!I74)
...

Sheet Closets
A1: Closets — Physical Storage Units
A2: Closet Name | B2: Type | C2: No. of Rows | D2: Location / Room | E2: Notes
A3: C1 | B3: PC Periphery | C3: 5 | D3: L3.3-E02-120
A4: C2 | B4: ELE stuff | C4: 5 | D4: L3.3-E02-120
A5: C3 | B5: ELE stuff | C5: 9 | D5: L3.3-E02-120
A6: C4 | B6: Tools | C6: 5 | D6: L3.3-E02-120
A7: C5 | B7: Projects | C7: 4 | D7: L3.3-E02-120
A8: C6 | B8: Misc | C8: 4 | D8: L3.3-E02-120
A9: C7 | B9: Boxes | C9: 5 | D9: L3.3-E02-120
A10: SCC1 | B10: ELE stuff | C10: 5 | D10: L3.3-E02-120
A11: SCC2 | B11: Tools | C11: 5 | D11: L3.3-E02-120
A12: SCC3 | B12: Tools | C12: 5 | D12: L3.3-E02-120
A13: SCC4 | B13: Projects | C13: 5 | D13: L3.3-E02-120
A14: SL5 | B14: Misc | C14: 4 | D14: L3.3-E02-120
... A16: SL3 | B16: cars | C16: 5 | D16: L3.3-E02-120
A17: SL2 | C17: 5 | D17: L3.3-E02-120
A18: SL1 | C18: 4 | D18: L3.3-E02-120

Sheet Bins
A1: Bins — Storage Containers
A2: Bin Name | B2: Closet | C2: Row | D2: Position | E2: Notes
A3: Empty (C1-R1-P1) | B3: C1 | C3: 1 | D3: 1
A4: Dell docking Cord | B4: C1 | C4: 1 | D4: 2
A5: Empty (C1-R1-P3) | B5: C1 | C5: 1 | D5: 3
A6: Empty (C1-R1-P4) | B6: C1 | C6: 1 | D6: 4
A7: Ethernet Cables | B7: C1 | C7: 2 | D7: 1
A8: 3.5 mm Jack | B8: C1 | C8: 2 | D8: 2
A9: Display cables | B9: C1 | C9: 2 | D9: 3
A10: Empty (C1-R2-P4) | B10: C1 | C10: 2 | D10: 4
A11: USB Type B | B11: C1 | C11: 3 | D11: 1
A12: Empty (C1-R3-P2) | B12: C1 | C12: 3 | D12: 2
A13: Wireless Keyboard | B13: C1 | C13: 3 | D13: 3
A14: Empty (C1-R3-P4) | B14: C1 | C14: 3 | D14: 4
... A34: Small ESP 32 Microcontrollers | B34: C2 | C34: 4 | D34: 2
A35: RGB Shield For Arduino | C35: 4 | D35: 3
A36: Connectors and wiring | B36: C2 | C36: 4 | D36: 4
A37: Cables FF | B37: C2 | C37: 5 | D37: 1
A38: Cables MF | B38: C2 | C38: 5 | D38: 2
A39: Cables MM | B39: C2 | C39: 5 | D39: 3
A40: Cables Exoctic | B40: C2 | C40: 5 | D40: 4
A41: Hexagonal Key Wrenches | B41: C4 | C41: 1 | D41: 1
A42: Empty (C4-R1-P2) | B42: C4 | C42: 1 | D42: 2
A43: Empty (C4-R1-P3) | B43: C4 | C43: 1 | D43: 3
A44: Mounting Hole templates | B44: C4 | C44: 1 | D44: 4
A45: Caliper Boxes | B45: C4 | C45: 2 | D45: 1
A46: Prof. Göbels Raspery Pi | B46: C4 | C46: 2 | D46: 2
A47: Multimeters | B47: C4 | C47: 2 | D47: 3
... A224: Dell Misc | B224: SL1 | C224: 1 | D224: 1
A225: Dell metalic parts
A226: Dell case cables
A227: Dell case parts | C227: 2
A228: Two projects
A229: Workstation cables
A230: SATA cables
A231: Denver WIFI Cam 4K ACK-8060W | B231: SL2 | C231: 2 | D231: 2
A232: Dell Metal Parts | B232: SL1 | C232: 1 | D232: 2
A233: PC case cables | B233: SL1 | C233: 1 | D233: 3
A234: Storage units holders? | B234: SL1 | C234: 2 | D234: 1
A235: Earthing Plugs | B235: SL1 | C235: 2 | D235: 2
...

Sheet Inventory
A1: Inventory — Items
A2: Item Name | B2: Code / Barcode | C2: Available Qty | D2: Bin | E2: Closet | F2: Condition | G2: Notes | H2: Total Qty
A3: Dell Docking cord | C3: =IF(A3="","",H3-SUMPRODUCT(('Checkout Log'!$A$3:$A$302=A3)*('Checkout Log'!$K$3:$K$302<>"Returned")*N('Checkout Log'!$B$3:$B$302))) -> 10 | D3: Dell docking Cord | E3: =IF(D3="","",IFERROR(VLOOKUP(D3,Bins!$A:$B,2,0),"—")) -> C1 | F3: Unknown | H3: 10
A4: Ethernet Cables | C4: =IF(A4="","",H4-SUMPRODUCT(('Checkout Log'!$A$3:$A$302=A4)*('Checkout Log'!$K$3:$K$302<>"Returned")*N('Checkout Log'!$B$3:$B$302))) -> 10 | D4: Ethernet Cables | E4: =IF(D4="","",IFERROR(VLOOKUP(D4,Bins!$A:$B,2,0),"—")) -> C1 | F4: Unknown | H4: 10
A5: 3.5 mm Jack | C5: =IF(A5="","",H5-SUMPRODUCT(('Checkout Log'!$A$3:$A$302=A5)*('Checkout Log'!$K$3:$K$302<>"Returned")*N('Checkout Log'!$B$3:$B$302))) -> 16 | D5: 3.5 mm Jack | E5: =IF(D5="","",IFERROR(VLOOKUP(D5,Bins!$A:$B,2,0),"—")) -> C1 | F5: Unknown | H5: 16
A6: USB Type B 2.0 | C6: =IF(A6="","",H6-SUMPRODUCT(('Checkout Log'!$A$3:$A$302=A6)*('Checkout Log'!$K$3:$K$302<>"Returned")*N('Checkout Log'!$B$3:$B$302))) -> 30 | D6: USB Type B 2.0 | E6: =IF(D6="","",IFERROR(VLOOKUP(D6,Bins!$A:$B,2,0),"—")) -> C6 | F6: Unknown | H6: 30
A7: Dell Laptops | C7: =IF(A7="","",H7-SUMPRODUCT(('Checkout Log'!$A$3:$A$302=A7)*('Checkout Log'!$K$3:$K$302<>"Returned")*N('Checkout Log'!$B$3:$B$302))) -> 2 | D7: Dell Laptops | E7: =IF(D7="","",IFERROR(VLOOKUP(D7,Bins!$A:$B,2,0),"—")) -> C1 | F7: Unknown | H7: 2
A8: Wired Keyboard HP H3CS3AA DE | C8: =IF(A8="","",H8-SUMPRODUCT(('Checkout Log'!$A$3:$A$302=A8)*('Checkout Log'!$K$3:$K$302<>"Returned")*N('Checkout Log'!$B$3:$B$302))) -> 2 | D8: Wired Keyboard DE | E8: =IF(D8="","",IFERROR(VLOOKUP(D8,Bins!$A:$B,2,0),"—")) -> C1 | F8: Unknown | H8: 2
A9: Wired Keyboard DELL KB216t DE | C9: =IF(A9="","",H9-SUMPRODUCT(('Checkout Log'!$A$3:$A$302=A9)*('Checkout Log'!$K$3:$K$302<>"Returned")*N('Checkout Log'!$B$3:$B$302))) -> 6 | D9: Wired Keyboard DE | E9: =IF(D9="","",IFERROR(VLOOKUP(D9,Bins!$A:$B,2,0),"—")) -> C1 | F9: Unknown | H9: 6
A10: Wired Keyboard Fujitsu KB 410 C DE | C10: =IF(A10="","",H10-SUMPRODUCT(('Checkout Log'!$A$3:$A$302=A10)*('Checkout Log'!$K$3:$K$302<>"Returned")*N('Checkout Log'!$B$3:$B$302))) -> 1 | D10: Wired Keyboard DE | E10: =IF(D10="","",IFERROR(VLOOKUP(D10,Bins!$A:$B,2,0),"—")) -> C1 | F10: Unknown | H10: 1
A11: Wired Keyboard CHERRY KC 6000 SLIM DE | C11: =IF(A11="","",H11-SUMPRODUCT(('Checkout Log'!$A$3:$A$302=A11)*('Checkout Log'!$K$3:$K$302<>"Returned")*N('Checkout Log'!$B$3:$B$302))) -> 4 | D11: Wired Keyboard DE | E11: =IF(D11="","",IFERROR(VLOOKUP(D11,Bins!$A:$B,2,0),"—")) -> C1 | F11: Unknown | H11: 4
A12: Varta CR20250 Lithum Cell 3v battery | C12: =IF(A12="","",H12-SUMPRODUCT(('Checkout Log'!$A$3:$A$302=A12)*('Checkout Log'!$K$3:$K$302<>"Returned")*N('Checkout Log'!$B$3:$B$302))) -> 11 | D12: Lithium Coin Cells mix | E12: =IF(D12="","",IFERROR(VLOOKUP(D12,Bins!$A:$B,2,0),"—")) -> C2 | F12: Unknown | H12: 11
A13: Varta V13GA/LR44 Lithum Cell 1.5v Battery | C13: =IF(A13="","",H13-SUMPRODUCT(('Checkout Log'!$A$3:$A$302=A13)*('Checkout Log'!$K$3:$K$302<>"Returned")*N('Checkout Log'!$B$3:$B$302))) -> 5 | D13: Lithium Coin Cells mix | E13: =IF(D13="","",IFERROR(VLOOKUP(D13,Bins!$A:$B,2,0),"—")) -> C2 | F13: Unknown | H13: 5
A14: Long Red Boxes | C14: =IF(A14="","",H14-SUMPRODUCT(('Checkout Log'!$A$3:$A$302=A14)*('Checkout Log'!$K$3:$K$302<>"Returned")*N('Checkout Log'!$B$3:$B$302))) -> 20 | D14: Long Red Boxes | E14: =IF(D14="","",IFERROR(VLOOKUP(D14,Bins!$A:$B,2,0),"—")) -> C7 | F14: Unknown | H14: 20
... A39: Battery storage ENEROID EN 10LI | C39: =IF(A39="","",H39-SUMPRODUCT(('Checkout Log'!$A$3:$A$302=A39)*('Checkout Log'!$K$3:$K$302<>"Returned")*N('Checkout Log'!$B$3:$B$302))) -> 5 | D39: Battery Storage ENEROID | E39: =IF(D39="","",IFERROR(VLOOKUP(D39,Bins!$A:$B,2,0),"—")) -> C2 | F39: Unknown | H39: 5
A40: STM32F756 Nucleo-144 Microcontroller | C40: =IF(A40="","",H40-SUMPRODUCT(('Checkout Log'!$A$3:$A$302=A40)*('Checkout Log'!$K$3:$K$302<>"Returned")*N('Checkout Log'!$B$3:$B$302))) -> 2 | D40: STM 32 Microcontrollers | E40: =IF(D40="","",IFERROR(VLOOKUP(D40,Bins!$A:$B,2,0),"—")) -> C2 | F40: Unknown | G40: 2 rented by Narmada | H40: 4
A41: STM32F411 Nucleo-64 Microcontroller | C41: =IF(A41="","",H41-SUMPRODUCT(('Checkout Log'!$A$3:$A$302=A41)*('Checkout Log'!$K$3:$K$302<>"Returned")*N('Checkout Log'!$B$3:$B$302))) -> 2 | D41: STM 32 Microcontrollers | E41: =IF(D41="","",IFERROR(VLOOKUP(D41,Bins!$A:$B,2,0),"—")) -> C2 | F41: Unknown | H41: 2
A42: STM32F030 Nucleo-64 Microcontroller | C42: =IF(A42="","",H42-SUMPRODUCT(('Checkout Log'!$A$3:$A$302=A42)*('Checkout Log'!$K$3:$K$302<>"Returned")*N('Checkout Log'!$B$3:$B$302))) -> 1 | D42: STM 32 Microcontrollers | E42: =IF(D42="","",IFERROR(VLOOKUP(D42,Bins!$A:$B,2,0),"—")) -> C2 | F42: Unknown | H42: 1
A43: STM32L152 Nucleo-64 Microcontroller | C43: =IF(A43="","",H43-SUMPRODUCT(('Checkout Log'!$A$3:$A$302=A43)*('Checkout Log'!$K$3:$K$302<>"Returned")*N('Checkout Log'!$B$3:$B$302))) -> 5 | D43: STM 32 Microcontrollers | E43: =IF(D43="","",IFERROR(VLOOKUP(D43,Bins!$A:$B,2,0),"—")) -> C2 | F43: Unknown | H43: 5
A44: TinyPICO ESP32 Dev board Microcontroller | C44: =IF(A44="","",H44-SUMPRODUCT(('Checkout Log'!$A$3:$A$302=A44)*('Checkout Log'!$K$3:$K$302<>"Returned")*N('Checkout Log'!$B$3:$B$302))) -> 25 | D44: Small ESP 32 Microcontrollers | E44: =IF(D44="","",IFERROR(VLOOKUP(D44,Bins!$A:$B,2,0),"—")) -> C2 | F44: Unknown | H44: 25
A45: Teensy 4.0 32 bit Microcontroller | C45: =IF(A45="","",H45-SUMPRODUCT(('Checkout Log'!$A$3:$A$302=A45)*('Checkout Log'!$K$3:$K$302<>"Returned")*N('Checkout Log'!$B$3:$B$302))) -> 9 | D45: Small ESP 32 Microcontrollers | E45: =IF(D45="","",IFERROR(VLOOKUP(D45,Bins!$A:$B,2,0),"—")) -> C2 | F45: Unknown | H45: 9
A46: veleman-kit RGB SHIELD FOR ARDUINO | C46: =IF(A46="","",H46-SUMPRODUCT(('Checkout Log'!$A$3:$A$302=A46)*('Checkout Log'!$K$3:$K$302<>"Returned")*N('Checkout Log'!$B$3:$B$302))) -> 10 | D46: RGB Shield For Arduino | E46: =IF(D46="","",IFERROR(VLOOKUP(D46,Bins!$A:$B,2,0),"—")) -> 0 | F46: Unknown | H46: 10
A47: TRU components, Spade connector set 260pc | C47: =IF(A47="","",H47-SUMPRODUCT(('Checkout Log'!$A$3:$A$302=A47)*('Checkout Log'!$K$3:$K$302<>"Returned")*N('Checkout Log'!$B$3:$B$302))) -> 2 | E47: =IF(D47="","",IFERROR(VLOOKUP(D47,Bins!$A:$B,2,0),"—")) | F47: Unknown | H47: 2
A48: TRU components Crimp/Heat-sink connector assortment 382 pc. | C48: =IF(A48="","",H48-SUMPRODUCT(('Checkout Log'!$A$3:$A$302=A48)*('Checkout Log'!$K$3:$K$302<>"Returned")*N('Checkout Log'!$B$3:$B$302))) -> 1 | D48: Connectors and wiring | E48: =IF(D48="","",IFERROR(VLOOKUP(D48,Bins!$A:$B,2,0),"—")) -> C2 | F48: Unknown | H48: 1
A49: Conrad Crimp connector set 450 pc. | C49: =IF(A49="","",H49-SUMPRODUCT(('Checkout Log'!$A$3:$A$302=A49)*('Checkout Log'!$K$3:$K$302<>"Returned")*N('Checkout Log'!$B$3:$B$302))) -> 1 | D49: Connectors and wiring | E49: =IF(D49="","",IFERROR(VLOOKUP(D49,Bins!$A:$B,2,0),"—")) -> C2 | F49: Unknown | H49: 1
A50: Conrad Wiring set 350 pc. | C50: =IF(A50="","",H50-SUMPRODUCT(('Checkout Log'!$A$3:$A$302=A50)*('Checkout Log'!$K$3:$K$302<>"Returned")*N('Checkout Log'!$B$3:$B$302))) -> 0 | D50: Connectors and wiring | E50: =IF(D50="","",IFERROR(VLOOKUP(D50,Bins!$A:$B,2,0),"—")) -> C2 | F50: Unknown | H50: 0
A51: STM32MP157C-DK2 Microcontroller | C51: =IF(A51="","",H51-SUMPRODUCT(('Checkout Log'!$A$3:$A$302=A51)*('Checkout Log'!$K$3:$K$302<>"Returned")*N('Checkout Log'!$B$3:$B$302))) -> 0 | D51: STM 32 Microcontrollers | E51: =IF(D51="","",IFERROR(VLOOKUP(D51,Bins!$A:$B,2,0),"—")) -> C2 | F51: Unknown | G51: 3 rented by shehan (project work) | H51: 3
A52: SUNON small fan DC12V | C52: =IF(A52="","",H52-SUMPRODUCT(('Checkout Log'!$A$3:$A$302=A52)*('Checkout Log'!$K$3:$K$302<>"Returned")*N('Checkout Log'!$B$3:$B$302))) -> 1 | D52: Small fan/Small Electric Lock/L298N/DC-DC Boost module | E52: =IF(D52="","",IFERROR(VLOOKUP(D52,Bins!$A:$B,2,0),"—")) -> C3 | F52: Unknown | H52: 1
A53: Small Electric Lock | C53: =IF(A53="","",H53-SUMPRODUCT(('Checkout Log'!$A$3:$A$302=A53)*('Checkout Log'!$K$3:$K$302<>"Returned")*N('Checkout Log'!$B$3:$B$302))) -> 0 | D53: Small fan/Small Electric Lock/L298N/DC-DC Boost module | E53: =IF(D53="","",IFERROR(VLOOKUP(D53,Bins!$A:$B,2,0),"—")) -> C3 | F53: Unknown | H53: 0
A54: L298N Motor Driver | C54: =IF(A54="","",H54-SUMPRODUCT(('Checkout Log'!$A$3:$A$302=A54)*('Checkout Log'!$K$3:$K$302<>"Returned")*N('Checkout Log'!$B$3:$B$302))) -> 5 | D54: Small fan/Small Electric Lock/L298N/DC-DC Boost module | E54: =IF(D54="","",IFERROR(VLOOKUP(D54,Bins!$A:$B,2,0),"—")) -> C3 | F54: Unknown | H54: 5
A55: velleman DC-DC Converter VMA403 | C55: =IF(A55="","",H55-SUMPRODUCT(('Checkout Log'!$A$3:$A$302=A55)*('Checkout Log'!$K$3:$K$302<>"Returned")*N('Checkout Log'!$B$3:$B$302))) -> 2 | D55: Small fan/Small Electric Lock/L298N/DC-DC Boost module | E55: =IF(D55="","",IFERROR(VLOOKUP(D55,Bins!$A:$B,2,0),"—")) -> C3 | F55: Unknown | H55: 2
A56: MegaPi Microcontroller | C56: =IF(A56="","",H56-SUMPRODUCT(('Checkout Log'!$A$3:$A$302=A56)*('Checkout Log'!$K$3:$K$302<>"Returned")*N('Checkout Log'!$B$3:$B$302))) -> 2 | D56: MegaPI with motors/ Arduino Motor Shield Rev3/ATmega328PB Xplained Mini/ velleman Motor and Power Shield/ pcDUINO | E56: =IF(D56="","",IFERROR(VLOOKUP(D56,Bins!$A:$B,2,0),"—")) -> C3 | F56: Unknown | H56: 2
A57: MakeBlock 25mm DC Encoder motor 9V | C57: =IF(A57="","",H57-SUMPRODUCT(('Checkout Log'!$A$3:$A$302=A57)*('Checkout Log'!$K$3:$K$302<>"Returned")*N('Checkout Log'!$B$3:$B$302))) -> 2 | D57: MegaPI with motors/ Arduino Motor Shield Rev3/ATmega328PB Xplained Mini/ velleman Motor and Power Shield/ pcDUINO | E57: =IF(D57="","",IFERROR(VLOOKUP(D57,Bins!$A:$B,2,0),"—")) -> C3 | F57: Unknown | H57: 2
A58: Arduino MOTOR SHIELD Rev 4 Microcontroller | C58: =IF(A58="","",H58-SUMPRODUCT(('Checkout Log'!$A$3:$A$302=A58)*('Checkout Log'!$K$3:$K$302<>"Returned")*N('Checkout Log'!$B$3:$B$302))) -> 2 | D58: MegaPI with motors/ Arduino Motor Shield Rev3/ATmega328PB Xplained Mini/ velleman Motor and Power Shield/ pcDUINO | E58: =IF(D58="","",IFERROR(VLOOKUP(D58,Bins!$A:$B,2,0),"—")) -> C3 | F58: Unknown | H58: 2
A59: Tmega328PB Xplained Mini | C59: =IF(A59="","",H59-SUMPRODUCT(('Checkout Log'!$A$3:$A$302=A59)*('Checkout Log'!$K$3:$K$302<>"Returned")*N('Checkout Log'!$B$3:$B$302))) -> 2 | D59: MegaPI with motors/ Arduino Motor Shield Rev3/ATmega328PB Xplained Mini/ velleman Motor and Power Shield/ pcDUINO | E59: =IF(D59="","",IFERROR(VLOOKUP(D59,Bins!$A:$B,2,0),"—")) -> C3 | F59: Unknown | H59: 2
A60: Velleman Motor and Power Shield | C60: =IF(A60="","",H60-SUMPRODUCT(('Checkout Log'!$A$3:$A$302=A60)*('Checkout Log'!$K$3:$K$302<>"Returned")*N('Checkout Log'!$B$3:$B$302))) -> 2 | D60: MegaPI with motors/ Arduino Motor Shield Rev3/ATmega328PB Xplained Mini/ velleman Motor and Power Shield/ pcDUINO | E60: =IF(D60="","",IFERROR(VLOOKUP(D60,Bins!$A:$B,2,0),"—")) -> C3 | F60: Unknown | H60: 2
A61: pcDUINO | C61: =IF(A61="","",H61-SUMPRODUCT(('Checkout Log'!$A$3:$A$302=A61)*('Checkout Log'!$K$3:$K$302<>"Returned")*N('Checkout Log'!$B$3:$B$302))) -> 0 | D61: MegaPI with motors/ Arduino Motor Shield Rev3/ATmega328PB Xplained Mini/ velleman Motor and Power Shield/ pcDUINO | E61: =IF(D61="","",IFERROR(VLOOKUP(D61,Bins!$A:$B,2,0),"—")) -> C3 | F61: Unknown | H61: 0
A62: Round Force Sensor FSR402 | C62: =IF(A62="","",H62-SUMPRODUCT(('Checkout Log'!$A$3:$A$302=A62)*('Checkout Log'!$K$3:$K$302<>"Returned")*N('Checkout Log'!$B$3:$B$302))) -> 0 | D62: Round Force Sensor FSR402/DHT21/Infrared Remote | E62: =IF(D62="","",IFERROR(VLOOKUP(D62,Bins!$A:$B,2,0),"—")) -> C3 | F62: Unknown | H62: 0
A63: DHT21 Analog humidity sensor | C63: =IF(A63="","",H63-SUMPRODUCT(('Checkout Log'!$A$3:$A$302=A63)*('Checkout Log'!$K$3:$K$302<>"Returned")*N('Checkout Log'!$B$3:$B$302))) -> 5 | D63: Round Force Sensor FSR402/DHT21/Infrared Remote | E63: =IF(D63="","",IFERROR(VLOOKUP(D63,Bins!$A:$B,2,0),"—")) -> C3 | F63: Unknown | H63: 5
... A87: Debo LED RGBY K855396 | C87: =IF(A87="","",H87-SUMPRODUCT(('Checkout Log'!$A$3:$A$302=A87)*('Checkout Log'!$K$3:$K$302<>"Returned")*N('Checkout Log'!$B$3:$B$302))) -> 46 | D87: Debo LED RGBY | E87: =IF(D87="","",IFERROR(VLOOKUP(D87,Bins!$A:$B,2,0),"—")) -> C3 | F87: Unknown | H87: 46
...

Sheet Checkout Log
A1: Checkout Log — Borrowing Events
A2: Item Name | B2: Qty | C2: Bin | D2: Closet | E2: Borrower Name | F2: Student/Staff ID | G2: SHK (processed by) | H2: Checkout Date | I2: Expected Return | J2: Returned Date | K2: Return Condition | L2: Status
A3: STM32F756 Nucleo-144 Microcontroller | B3: 2 | C3: =IF(A3="","",IFERROR(VLOOKUP(A3,Inventory!$A:$D,4,0),"—")) -> STM 32 Microcontrollers | D3: =IF(A3="","",IFERROR(VLOOKUP(A3,Inventory!$A:$E,5,0),"—")) -> C2 | E3: Narmada | L3: Checked Out
A4: STM32MP157C-DK2 Microcontroller | B4: 3 | C4: =IF(A4="","",IFERROR(VLOOKUP(A4,Inventory!$A:$D,4,0),"—")) -> STM 32 Microcontrollers | D4: =IF(A4="","",IFERROR(VLOOKUP(A4,Inventory!$A:$E,5,0),"—")) -> C2 | E4: Shehan | L4: Checked Out
A5: BitCraze CrazyFlie drone kit | B5: 1 | C5: =IF(A5="","",IFERROR(VLOOKUP(A5,Inventory!$A:$D,4,0),"—")) -> BitCraze CrazyFlie drone kit | D5: =IF(A5="","",IFERROR(VLOOKUP(A5,Inventory!$A:$E,5,0),"—")) -> SL2 | E5: domenic Drechsel | L5: Checked Out
A6: Servo Motor S35+XF | B6: 2 | C6: =IF(A6="","",IFERROR(VLOOKUP(A6,Inventory!$A:$D,4,0),"—")) -> Servo Motors | D6: =IF(A6="","",IFERROR(VLOOKUP(A6,Inventory!$A:$E,5,0),"—")) -> C3 | E6: MD Akram | L6: Checked Out
C7: =IF(A7="","",IFERROR(VLOOKUP(A7,Inventory!$A:$D,4,0),"—")) | D7: =IF(A7="","",IFERROR(VLOOKUP(A7,Inventory!$A:$E,5,0),"—"))
C8: =IF(A8="","",IFERROR(VLOOKUP(A8,Inventory!$A:$D,4,0),"—")) | D8: =IF(A8="","",IFERROR(VLOOKUP(A8,Inventory!$A:$E,5,0),"—"))
C9: =IF(A9="","",IFERROR(VLOOKUP(A9,Inventory!$A:$D,4,0),"—")) | D9: =IF(A9="","",IFERROR(VLOOKUP(A9,Inventory!$A:$E,5,0),"—"))
C10: =IF(A10="","",IFERROR(VLOOKUP(A10,Inventory!$A:$D,4,0),"—")) | D10: =IF(A10="","",IFERROR(VLOOKUP(A10,Inventory!$A:$E,5,0),"—"))
C11: =IF(A11="","",IFERROR(VLOOKUP(A11,Inventory!$A:$D,4,0),"—")) | D11: =IF(A11="","",IFERROR(VLOOKUP(A11,Inventory!$A:$E,5,0),"—"))
C12: =IF(A12="","",IFERROR(VLOOKUP(A12,Inventory!$A:$D,4,0),"—")) | D12: =IF(A12="","",IFERROR(VLOOKUP(A12,Inventory!$A:$E,5,0),"—"))
C13: =IF(A13="","",IFERROR(VLOOKUP(A13,Inventory!$A:$D,4,0),"—")) | D13: =IF(A13="","",IFERROR(VLOOKUP(A13,Inventory!$A:$E,5,0),"—"))
C14: =IF(A14="","",IFERROR(VLOOKUP(A14,Inventory!$A:$D,4,0),"—")) | D14: =IF(A14="","",IFERROR(VLOOKUP(A14,Inventory!$A:$E,5,0),"—"))
C15: =IF(A15="","",IFERROR(VLOOKUP(A15,Inventory!$A:$D,4,0),"—")) | D15: =IF(A15="","",IFERROR(VLOOKUP(A15,Inventory!$A:$E,5,0),"—"))
C16: =IF(A16="","",IFERROR(VLOOKUP(A16,Inventory!$A:$D,4,0),"—")) | D16: =IF(A16="","",IFERROR(VLOOKUP(A16,Inventory!$A:$E,5,0),"—"))
C17: =IF(A17="","",IFERROR(VLOOKUP(A17,Inventory!$A:$D,4,0),"—")) | D17: =IF(A17="","",IFERROR(VLOOKUP(A17,Inventory!$A:$E,5,0),"—"))
C18: =IF(A18="","",IFERROR(VLOOKUP(A18,Inventory!$A:$D,4,0),"—")) | D18: =IF(A18="","",IFERROR(VLOOKUP(A18,Inventory!$A:$E,5,0),"—"))
... C31: =IF(A31="","",IFERROR(VLOOKUP(A31,Inventory!$A:$D,4,0),"—")) | D31: =IF(A31="","",IFERROR(VLOOKUP(A31,Inventory!$A:$E,5,0),"—"))
C32: =IF(A32="","",IFERROR(VLOOKUP(A32,Inventory!$A:$D,4,0),"—"))
C33: =IF(A33="","",IFERROR(VLOOKUP(A33,Inventory!$A:$D,4,0),"—")) | D33: =IF(A33="","",IFERROR(VLOOKUP(A33,Inventory!$A:$E,5,0),"—"))
C34: =IF(A34="","",IFERROR(VLOOKUP(A34,Inventory!$A:$D,4,0),"—")) | D34: =IF(A34="","",IFERROR(VLOOKUP(A34,Inventory!$A:$E,5,0),"—"))
C35: =IF(A35="","",IFERROR(VLOOKUP(A35,Inventory!$A:$D,4,0),"—")) | D35: =IF(A35="","",IFERROR(VLOOKUP(A35,Inventory!$A:$E,5,0),"—"))
C36: =IF(A36="","",IFERROR(VLOOKUP(A36,Inventory!$A:$D,4,0),"—")) | D36: =IF(A36="","",IFERROR(VLOOKUP(A36,Inventory!$A:$E,5,0),"—"))
C37: =IF(A37="","",IFERROR(VLOOKUP(A37,Inventory!$A:$D,4,0),"—")) | D37: =IF(A37="","",IFERROR(VLOOKUP(A37,Inventory!$A:$E,5,0),"—"))
C38: =IF(A38="","",IFERROR(VLOOKUP(A38,Inventory!$A:$D,4,0),"—")) | D38: =IF(A38="","",IFERROR(VLOOKUP(A38,Inventory!$A:$E,5,0),"—"))
C39: =IF(A39="","",IFERROR(VLOOKUP(A39,Inventory!$A:$D,4,0),"—")) | D39: =IF(A39="","",IFERROR(VLOOKUP(A39,Inventory!$A:$E,5,0),"—"))
C40: =IF(A40="","",IFERROR(VLOOKUP(A40,Inventory!$A:$D,4,0),"—")) | D40: =IF(A40="","",IFERROR(VLOOKUP(A40,Inventory!$A:$E,5,0),"—"))
C41: =IF(A41="","",IFERROR(VLOOKUP(A41,Inventory!$A:$D,4,0),"—")) | D41: =IF(A41="","",IFERROR(VLOOKUP(A41,Inventory!$A:$E,5,0),"—"))
C42: =IF(A42="","",IFERROR(VLOOKUP(A42,Inventory!$A:$D,4,0),"—")) | D42: =IF(A42="","",IFERROR(VLOOKUP(A42,Inventory!$A:$E,5,0),"—"))
C43: =IF(A43="","",IFERROR(VLOOKUP(A43,Inventory!$A:$D,4,0),"—")) | D43: =IF(A43="","",IFERROR(VLOOKUP(A43,Inventory!$A:$E,5,0),"—"))
C44: =IF(A44="","",IFERROR(VLOOKUP(A44,Inventory!$A:$D,4,0),"—")) | D44: =IF(A44="","",IFERROR(VLOOKUP(A44,Inventory!$A:$E,5,0),"—"))
... C302: =IF(A302="","",IFERROR(VLOOKUP(A302,Inventory!$A:$D,4,0),"—")) | D302: =IF(A302="","",IFERROR(VLOOKUP(A302,Inventory!$A:$E,5,0),"—"))

Sheet Search
A1: Search — Find Any Item
A2: Type item name: | D2: ← type part of an item name; results below update automatically. Leave blank to show everything.
A4: Item Name | B4: Code / Barcode | C4: Qty | D4: Bin | E4: Closet | F4: Condition | G4: Notes
A5: =IFERROR(IF(INDEX(Inventory!A:A,SMALL($H$5:$H$304,1))="","",INDEX(Inventory!A:A,SMALL($H$5:$H$304,1))),"") | B5: =IFERROR(IF(INDEX(Inventory!B:B,SMALL($H$5:$H$304,1))="","",INDEX(Inventory!B:B,SMALL($H$5:$H$304,1))),"") | C5: =IFERROR(IF(INDEX(Inventory!C:C,SMALL($H$5:$H$304,1))="","",INDEX(Inventory!C:C,SMALL($H$5:$H$304,1))),"") | D5: =IFERROR(IF(INDEX(Inventory!D:D,SMALL($H$5:$H$304,1))="","",INDEX(Inventory!D:D,SMALL($H$5:$H$304,1))),"") | E5: =IFERROR(IF(INDEX(Inventory!E:E,SMALL($H$5:$H$304,1))="","",INDEX(Inventory!E:E,SMALL($H$5:$H$304,1))),"") | F5: =IFERROR(IF(INDEX(Inventory!F:F,SMALL($H$5:$H$304,1))="","",INDEX(Inventory!F:F,SMALL($H$5:$H$304,1))),"") | G5: =IFERROR(IF(INDEX(Inventory!G:G,SMALL($H$5:$H$304,1))="","",INDEX(Inventory!G:G,SMALL($H$5:$H$304,1))),"") | H5: =IF(Inventory!A3="","",IF(ISNUMBER(SEARCH($C$2,Inventory!A3)),ROW(Inventory!A3),""))
A6: =IFERROR(IF(INDEX(Inventory!A:A,SMALL($H$5:$H$304,2))="","",INDEX(Inventory!A:A,SMALL($H$5:$H$304,2))),"") | B6: =IFERROR(IF(INDEX(Inventory!B:B,SMALL($H$5:$H$304,2))="","",INDEX(Inventory!B:B,SMALL($H$5:$H$304,2))),"") | C6: =IFERROR(IF(INDEX(Inventory!C:C,SMALL($H$5:$H$304,2))="","",INDEX(Inventory!C:C,SMALL($H$5:$H$304,2))),"") | D6: =IFERROR(IF(INDEX(Inventory!D:D,SMALL($H$5:$H$304,2))="","",INDEX(Inventory!D:D,SMALL($H$5:$H$304,2))),"") | E6: =IFERROR(IF(INDEX(Inventory!E:E,SMALL($H$5:$H$304,2))="","",INDEX(Inventory!E:E,SMALL($H$5:$H$304,2))),"") | F6: =IFERROR(IF(INDEX(Inventory!F:F,SMALL($H$5:$H$304,2))="","",INDEX(Inventory!F:F,SMALL($H$5:$H$304,2))),"") | G6: =IFERROR(IF(INDEX(Inventory!G:G,SMALL($H$5:$H$304,2))="","",INDEX(Inventory!G:G,SMALL($H$5:$H$304,2))),"") | H6: =IF(Inventory!A4="","",IF(ISNUMBER(SEARCH($C$2,Inventory!A4)),ROW(Inventory!A4),""))
A7: =IFERROR(IF(INDEX(Inventory!A:A,SMALL($H$5:$H$304,3))="","",INDEX(Inventory!A:A,SMALL($H$5:$H$304,3))),"") | B7: =IFERROR(IF(INDEX(Inventory!B:B,SMALL($H$5:$H$304,3))="","",INDEX(Inventory!B:B,SMALL($H$5:$H$304,3))),"") | C7: =IFERROR(IF(INDEX(Inventory!C:C,SMALL($H$5:$H$304,3))="","",INDEX(Inventory!C:C,SMALL($H$5:$H$304,3))),"") | D7: =IFERROR(IF(INDEX(Inventory!D:D,SMALL($H$5:$H$304,3))="","",INDEX(Inventory!D:D,SMALL($H$5:$H$304,3))),"") | E7: =IFERROR(IF(INDEX(Inventory!E:E,SMALL($H$5:$H$304,3))="","",INDEX(Inventory!E:E,SMALL($H$5:$H$304,3))),"") | F7: =IFERROR(IF(INDEX(Inventory!F:F,SMALL($H$5:$H$304,3))="","",INDEX(Inventory!F:F,SMALL($H$5:$H$304,3))),"") | G7: =IFERROR(IF(INDEX(Inventory!G:G,SMALL($H$5:$H$304,3))="","",INDEX(Inventory!G:G,SMALL($H$5:$H$304,3))),"") | H7: =IF(Inventory!A5="","",IF(ISNUMBER(SEARCH($C$2,Inventory!A5)),ROW(Inventory!A5),""))
A8: =IFERROR(IF(INDEX(Inventory!A:A,SMALL($H$5:$H$304,4))="","",INDEX(Inventory!A:A,SMALL($H$5:$H$304,4))),"") | B8: =IFERROR(IF(INDEX(Inventory!B:B,SMALL($H$5:$H$304,4))="","",INDEX(Inventory!B:B,SMALL($H$5:$H$304,4))),"") | C8: =IFERROR(IF(INDEX(Inventory!C:C,SMALL($H$5:$H$304,4))="","",INDEX(Inventory!C:C,SMALL($H$5:$H$304,4))),"") | D8: =IFERROR(IF(INDEX(Inventory!D:D,SMALL($H$5:$H$304,4))="","",INDEX(Inventory!D:D,SMALL($H$5:$H$304,4))),"") | E8: =IFERROR(IF(INDEX(Inventory!E:E,SMALL($H$5:$H$304,4))="","",INDEX(Inventory!E:E,SMALL($H$5:$H$304,4))),"") | F8: =IFERROR(IF(INDEX(Inventory!F:F,SMALL($H$5:$H$304,4))="","",INDEX(Inventory!F:F,SMALL($H$5:$H$304,4))),"") | G8: =IFERROR(IF(INDEX(Inventory!G:G,SMALL($H$5:$H$304,4))="","",INDEX(Inventory!G:G,SMALL($H$5:$H$304,4))),"") | H8: =IF(Inventory!A6="","",IF(ISNUMBER(SEARCH($C$2,Inventory!A6)),ROW(Inventory!A6),""))
A9: =IFERROR(IF(INDEX(Inventory!A:A,SMALL($H$5:$H$304,5))="","",INDEX(Inventory!A:A,SMALL($H$5:$H$304,5))),"") | B9: =IFERROR(IF(INDEX(Inventory!B:B,SMALL($H$5:$H$304,5))="","",INDEX(Inventory!B:B,SMALL($H$5:$H$304,5))),"") | C9: =IFERROR(IF(INDEX(Inventory!C:C,SMALL($H$5:$H$304,5))="","",INDEX(Inventory!C:C,SMALL($H$5:$H$304,5))),"") | D9: =IFERROR(IF(INDEX(Inventory!D:D,SMALL($H$5:$H$304,5))="","",INDEX(Inventory!D:D,SMALL($H$5:$H$304,5))),"") | E9: =IFERROR(IF(INDEX(Inventory!E:E,SMALL($H$5:$H$304,5))="","",INDEX(Inventory!E:E,SMALL($H$5:$H$304,5))),"") | F9: =IFERROR(IF(INDEX(Inventory!F:F,SMALL($H$5:$H$304,5))="","",INDEX(Inventory!F:F,SMALL($H$5:$H$304,5))),"") | G9: =IFERROR(IF(INDEX(Inventory!G:G,SMALL($H$5:$H$304,5))="","",INDEX(Inventory!G:G,SMALL($H$5:$H$304,5))),"") | H9: =IF(Inventory!A7="","",IF(ISNUMBER(SEARCH($C$2,Inventory!A7)),ROW(Inventory!A7),""))
A10: =IFERROR(IF(INDEX(Inventory!A:A,SMALL($H$5:$H$304,6))="","",INDEX(Inventory!A:A,SMALL($H$5:$H$304,6))),"") | B10: =IFERROR(IF(INDEX(Inventory!B:B,SMALL($H$5:$H$304,6))="","",INDEX(Inventory!B:B,SMALL($H$5:$H$304,6))),"") | C10: =IFERROR(IF(INDEX(Inventory!C:C,SMALL($H$5:$H$304,6))="","",INDEX(Inventory!C:C,SMALL($H$5:$H$304,6))),"") | D10: =IFERROR(IF(INDEX(Inventory!D:D,SMALL($H$5:$H$304,6))="","",INDEX(Inventory!D:D,SMALL($H$5:$H$304,6))),"") | E10: =IFERROR(IF(INDEX(Inventory!E:E,SMALL($H$5:$H$304,6))="","",INDEX(Inventory!E:E,SMALL($H$5:$H$304,6))),"") | F10: =IFERROR(IF(INDEX(Inventory!F:F,SMALL($H$5:$H$304,6))="","",INDEX(Inventory!F:F,SMALL($H$5:$H$304,6))),"") | G10: =IFERROR(IF(INDEX(Inventory!G:G,SMALL($H$5:$H$304,6))="","",INDEX(Inventory!G:G,SMALL($H$5:$H$304,6))),"") | H10: =IF(Inventory!A8="","",IF(ISNUMBER(SEARCH($C$2,Inventory!A8)),ROW(Inventory!A8),""))
A11: =IFERROR(IF(INDEX(Inventory!A:A,SMALL($H$5:$H$304,7))="","",INDEX(Inventory!A:A,SMALL($H$5:$H$304,7))),"") | B11: =IFERROR(IF(INDEX(Inventory!B:B,SMALL($H$5:$H$304,7))="","",INDEX(Inventory!B:B,SMALL($H$5:$H$304,7))),"") | C11: =IFERROR(IF(INDEX(Inventory!C:C,SMALL($H$5:$H$304,7))="","",INDEX(Inventory!C:C,SMALL($H$5:$H$304,7))),"") | D11: =IFERROR(IF(INDEX(Inventory!D:D,SMALL($H$5:$H$304,7))="","",INDEX(Inventory!D:D,SMALL($H$5:$H$304,7))),"") | E11: =IFERROR(IF(INDEX(Inventory!E:E,SMALL($H$5:$H$304,7))="","",INDEX(Inventory!E:E,SMALL($H$5:$H$304,7))),"") | F11: =IFERROR(IF(INDEX(Inventory!F:F,SMALL($H$5:$H$304,7))="","",INDEX(Inventory!F:F,SMALL($H$5:$H$304,7))),"") | G11: =IFERROR(IF(INDEX(Inventory!G:G,SMALL($H$5:$H$304,7))="","",INDEX(Inventory!G:G,SMALL($H$5:$H$304,7))),"") | H11: =IF(Inventory!A9="","",IF(ISNUMBER(SEARCH($C$2,Inventory!A9)),ROW(Inventory!A9),""))
A12: =IFERROR(IF(INDEX(Inventory!A:A,SMALL($H$5:$H$304,8))="","",INDEX(Inventory!A:A,SMALL($H$5:$H$304,8))),"") | B12: =IFERROR(IF(INDEX(Inventory!B:B,SMALL($H$5:$H$304,8))="","",INDEX(Inventory!B:B,SMALL($H$5:$H$304,8))),"") | C12: =IFERROR(IF(INDEX(Inventory!C:C,SMALL($H$5:$H$304,8))="","",INDEX(Inventory!C:C,SMALL($H$5:$H$304,8))),"") | D12: =IFERROR(IF(INDEX(Inventory!D:D,SMALL($H$5:$H$304,8))="","",INDEX(Inventory!D:D,SMALL($H$5:$H$304,8))),"") | E12: =IFERROR(IF(INDEX(Inventory!E:E,SMALL($H$5:$H$304,8))="","",INDEX(Inventory!E:E,SMALL($H$5:$H$304,8))),"") | F12: =IFERROR(IF(INDEX(Inventory!F:F,SMALL($H$5:$H$304,8))="","",INDEX(Inventory!F:F,SMALL($H$5:$H$304,8))),"") | G12: =IFERROR(IF(INDEX(Inventory!G:G,SMALL($H$5:$H$304,8))="","",INDEX(Inventory!G:G,SMALL($H$5:$H$304,8))),"") | H12: =IF(Inventory!A10="","",IF(ISNUMBER(SEARCH($C$2,Inventory!A10)),ROW(Inventory!A10),""))
A13: =IFERROR(IF(INDEX(Inventory!A:A,SMALL($H$5:$H$304,9))="","",INDEX(Inventory!A:A,SMALL($H$5:$H$304,9))),"") | B13: =IFERROR(IF(INDEX(Inventory!B:B,SMALL($H$5:$H$304,9))="","",INDEX(Inventory!B:B,SMALL($H$5:$H$304,9))),"") | C13: =IFERROR(IF(INDEX(Inventory!C:C,SMALL($H$5:$H$304,9))="","",INDEX(Inventory!C:C,SMALL($H$5:$H$304,9))),"") | D13: =IFERROR(IF(INDEX(Inventory!D:D,SMALL($H$5:$H$304,9))="","",INDEX(Inventory!D:D,SMALL($H$5:$H$304,9))),"") | E13: =IFERROR(IF(INDEX(Inventory!E:E,SMALL($H$5:$H$304,9))="","",INDEX(Inventory!E:E,SMALL($H$5:$H$304,9))),"") | F13: =IFERROR(IF(INDEX(Inventory!F:F,SMALL($H$5:$H$304,9))="","",INDEX(Inventory!F:F,SMALL($H$5:$H$304,9))),"") | G13: =IFERROR(IF(INDEX(Inventory!G:G,SMALL($H$5:$H$304,9))="","",INDEX(Inventory!G:G,SMALL($H$5:$H$304,9))),"") | H13: =IF(Inventory!A11="","",IF(ISNUMBER(SEARCH($C$2,Inventory!A11)),ROW(Inventory!A11),""))
A14: =IFERROR(IF(INDEX(Inventory!A:A,SMALL($H$5:$H$304,10))="","",INDEX(Inventory!A:A,SMALL($H$5:$H$304,10))),"") | B14: =IFERROR(IF(INDEX(Inventory!B:B,SMALL($H$5:$H$304,10))="","",INDEX(Inventory!B:B,SMALL($H$5:$H$304,10))),"") | C14: =IFERROR(IF(INDEX(Inventory!C:C,SMALL($H$5:$H$304,10))="","",INDEX(Inventory!C:C,SMALL($H$5:$H$304,10))),"") | D14: =IFERROR(IF(INDEX(Inventory!D:D,SMALL($H$5:$H$304,10))="","",INDEX(Inventory!D:D,SMALL($H$5:$H$304,10))),"") | E14: =IFERROR(IF(INDEX(Inventory!E:E,SMALL($H$5:$H$304,10))="","",INDEX(Inventory!E:E,SMALL($H$5:$H$304,10))),"") | F14: =IFERROR(IF(INDEX(Inventory!F:F,SMALL($H$5:$H$304,10))="","",INDEX(Inventory!F:F,SMALL($H$5:$H$304,10))),"") | G14: =IFERROR(IF(INDEX(Inventory!G:G,SMALL($H$5:$H$304,10))="","",INDEX(Inventory!G:G,SMALL($H$5:$H$304,10))),"") | H14: =IF(Inventory!A12="","",IF(ISNUMBER(SEARCH($C$2,Inventory!A12)),ROW(Inventory!A12),""))
A15: =IFERROR(IF(INDEX(Inventory!A:A,SMALL($H$5:$H$304,11))="","",INDEX(Inventory!A:A,SMALL($H$5:$H$304,11))),"") | B15: =IFERROR(IF(INDEX(Inventory!B:B,SMALL($H$5:$H$304,11))="","",INDEX(Inventory!B:B,SMALL($H$5:$H$304,11))),"") | C15: =IFERROR(IF(INDEX(Inventory!C:C,SMALL($H$5:$H$304,11))="","",INDEX(Inventory!C:C,SMALL($H$5:$H$304,11))),"") | D15: =IFERROR(IF(INDEX(Inventory!D:D,SMALL($H$5:$H$304,11))="","",INDEX(Inventory!D:D,SMALL($H$5:$H$304,11))),"") | E15: =IFERROR(IF(INDEX(Inventory!E:E,SMALL($H$5:$H$304,11))="","",INDEX(Inventory!E:E,SMALL($H$5:$H$304,11))),"") | F15: =IFERROR(IF(INDEX(Inventory!F:F,SMALL($H$5:$H$304,11))="","",INDEX(Inventory!F:F,SMALL($H$5:$H$304,11))),"") | G15: =IFERROR(IF(INDEX(Inventory!G:G,SMALL($H$5:$H$304,11))="","",INDEX(Inventory!G:G,SMALL($H$5:$H$304,11))),"") | H15: =IF(Inventory!A13="","",IF(ISNUMBER(SEARCH($C$2,Inventory!A13)),ROW(Inventory!A13),""))
A16: =IFERROR(IF(INDEX(Inventory!A:A,SMALL($H$5:$H$304,12))="","",INDEX(Inventory!A:A,SMALL($H$5:$H$304,12))),"") | B16: =IFERROR(IF(INDEX(Inventory!B:B,SMALL($H$5:$H$304,12))="","",INDEX(Inventory!B:B,SMALL($H$5:$H$304,12))),"") | C16: =IFERROR(IF(INDEX(Inventory!C:C,SMALL($H$5:$H$304,12))="","",INDEX(Inventory!C:C,SMALL($H$5:$H$304,12))),"") | D16: =IFERROR(IF(INDEX(Inventory!D:D,SMALL($H$5:$H$304,12))="","",INDEX(Inventory!D:D,SMALL($H$5:$H$304,12))),"") | E16: =IFERROR(IF(INDEX(Inventory!E:E,SMALL($H$5:$H$304,12))="","",INDEX(Inventory!E:E,SMALL($H$5:$H$304,12))),"") | F16: =IFERROR(IF(INDEX(Inventory!F:F,SMALL($H$5:$H$304,12))="","",INDEX(Inventory!F:F,SMALL($H$5:$H$304,12))),"") | G16: =IFERROR(IF(INDEX(Inventory!G:G,SMALL($H$5:$H$304,12))="","",INDEX(Inventory!G:G,SMALL($H$5:$H$304,12))),"") | H16: =IF(Inventory!A14="","",IF(ISNUMBER(SEARCH($C$2,Inventory!A14)),ROW(Inventory!A14),""))
A17: =IFERROR(IF(INDEX(Inventory!A:A,SMALL($H$5:$H$304,13))="","",INDEX(Inventory!A:A,SMALL($H$5:$H$304,13))),"") | B17: =IFERROR(IF(INDEX(Inventory!B:B,SMALL($H$5:$H$304,13))="","",INDEX(Inventory!B:B,SMALL($H$5:$H$304,13))),"") | C17: =IFERROR(IF(INDEX(Inventory!C:C,SMALL($H$5:$H$304,13))="","",INDEX(Inventory!C:C,SMALL($H$5:$H$304,13))),"") | D17: =IFERROR(IF(INDEX(Inventory!D:D,SMALL($H$5:$H$304,13))="","",INDEX(Inventory!D:D,SMALL($H$5:$H$304,13))),"") | E17: =IFERROR(IF(INDEX(Inventory!E:E,SMALL($H$5:$H$304,13))="","",INDEX(Inventory!E:E,SMALL($H$5:$H$304,13))),"") | F17: =IFERROR(IF(INDEX(Inventory!F:F,SMALL($H$5:$H$304,13))="","",INDEX(Inventory!F:F,SMALL($H$5:$H$304,13))),"") | G17: =IFERROR(IF(INDEX(Inventory!G:G,SMALL($H$5:$H$304,13))="","",INDEX(Inventory!G:G,SMALL($H$5:$H$304,13))),"") | H17: =IF(Inventory!A15="","",IF(ISNUMBER(SEARCH($C$2,Inventory!A15)),ROW(Inventory!A15),""))
A18: =IFERROR(IF(INDEX(Inventory!A:A,SMALL($H$5:$H$304,14))="","",INDEX(Inventory!A:A,SMALL($H$5:$H$304,14))),"") | B18: =IFERROR(IF(INDEX(Inventory!B:B,SMALL($H$5:$H$304,14))="","",INDEX(Inventory!B:B,SMALL($H$5:$H$304,14))),"") | C18: =IFERROR(IF(INDEX(Inventory!C:C,SMALL($H$5:$H$304,14))="","",INDEX(Inventory!C:C,SMALL($H$5:$H$304,14))),"") | D18: =IFERROR(IF(INDEX(Inventory!D:D,SMALL($H$5:$H$304,14))="","",INDEX(Inventory!D:D,SMALL($H$5:$H$304,14))),"") | E18: =IFERROR(IF(INDEX(Inventory!E:E,SMALL($H$5:$H$304,14))="","",INDEX(Inventory!E:E,SMALL($H$5:$H$304,14))),"") | F18: =IFERROR(IF(INDEX(Inventory!F:F,SMALL($H$5:$H$304,14))="","",INDEX(Inventory!F:F,SMALL($H$5:$H$304,14))),"") | G18: =IFERROR(IF(INDEX(Inventory!G:G,SMALL($H$5:$H$304,14))="","",INDEX(Inventory!G:G,SMALL($H$5:$H$304,14))),"") | H18: =IF(Inventory!A16="","",IF(ISNUMBER(SEARCH($C$2,Inventory!A16)),ROW(Inventory!A16),""))
A19: =IFERROR(IF(INDEX(Inventory!A:A,SMALL($H$5:$H$304,15))="","",INDEX(Inventory!A:A,SMALL($H$5:$H$304,15))),"") | B19: =IFERROR(IF(INDEX(Inventory!B:B,SMALL($H$5:$H$304,15))="","",INDEX(Inventory!B:B,SMALL($H$5:$H$304,15))),"") | C19: =IFERROR(IF(INDEX(Inventory!C:C,SMALL($H$5:$H$304,15))="","",INDEX(Inventory!C:C,SMALL($H$5:$H$304,15))),"") | D19: =IFERROR(IF(INDEX(Inventory!D:D,SMALL($H$5:$H$304,15))="","",INDEX(Inventory!D:D,SMALL($H$5:$H$304,15))),"") | E19: =IFERROR(IF(INDEX(Inventory!E:E,SMALL($H$5:$H$304,15))="","",INDEX(Inventory!E:E,SMALL($H$5:$H$304,15))),"") | F19: =IFERROR(IF(INDEX(Inventory!F:F,SMALL($H$5:$H$304,15))="","",INDEX(Inventory!F:F,SMALL($H$5:$H$304,15))),"") | G19: =IFERROR(IF(INDEX(Inventory!G:G,SMALL($H$5:$H$304,15))="","",INDEX(Inventory!G:G,SMALL($H$5:$H$304,15))),"") | H19: =IF(Inventory!A17="","",IF(ISNUMBER(SEARCH($C$2,Inventory!A17)),ROW(Inventory!A17),""))
A20: =IFERROR(IF(INDEX(Inventory!A:A,SMALL($H$5:$H$304,16))="","",INDEX(Inventory!A:A,SMALL($H$5:$H$304,16))),"") | B20: =IFERROR(IF(INDEX(Inventory!B:B,SMALL($H$5:$H$304,16))="","",INDEX(Inventory!B:B,SMALL($H$5:$H$304,16))),"") | C20: =IFERROR(IF(INDEX(Inventory!C:C,SMALL($H$5:$H$304,16))="","",INDEX(Inventory!C:C,SMALL($H$5:$H$304,16))),"") | D20: =IFERROR(IF(INDEX(Inventory!D:D,SMALL($H$5:$H$304,16))="","",INDEX(Inventory!D:D,SMALL($H$5:$H$304,16))),"") | E20: =IFERROR(IF(INDEX(Inventory!E:E,SMALL($H$5:$H$304,16))="","",INDEX(Inventory!E:E,SMALL($H$5:$H$304,16))),"") | F20: =IFERROR(IF(INDEX(Inventory!F:F,SMALL($H$5:$H$304,16))="","",INDEX(Inventory!F:F,SMALL($H$5:$H$304,16))),"") | G20: =IFERROR(IF(INDEX(Inventory!G:G,SMALL($H$5:$H$304,16))="","",INDEX(Inventory!G:G,SMALL($H$5:$H$304,16))),"") | H20: =IF(Inventory!A18="","",IF(ISNUMBER(SEARCH($C$2,Inventory!A18)),ROW(Inventory!A18),""))
A21: =IFERROR(IF(INDEX(Inventory!A:A,SMALL($H$5:$H$304,17))="","",INDEX(Inventory!A:A,SMALL($H$5:$H$304,17))),"") | B21: =IFERROR(IF(INDEX(Inventory!B:B,SMALL($H$5:$H$304,17))="","",INDEX(Inventory!B:B,SMALL($H$5:$H$304,17))),"") | C21: =IFERROR(IF(INDEX(Inventory!C:C,SMALL($H$5:$H$304,17))="","",INDEX(Inventory!C:C,SMALL($H$5:$H$304,17))),"") | D21: =IFERROR(IF(INDEX(Inventory!D:D,SMALL($H$5:$H$304,17))="","",INDEX(Inventory!D:D,SMALL($H$5:$H$304,17))),"") | E21: =IFERROR(IF(INDEX(Inventory!E:E,SMALL($H$5:$H$304,17))="","",INDEX(Inventory!E:E,SMALL($H$5:$H$304,17))),"") | F21: =IFERROR(IF(INDEX(Inventory!F:F,SMALL($H$5:$H$304,17))="","",INDEX(Inventory!F:F,SMALL($H$5:$H$304,17))),"") | G21: =IFERROR(IF(INDEX(Inventory!G:G,SMALL($H$5:$H$304,17))="","",INDEX(Inventory!G:G,SMALL($H$5:$H$304,17))),"") | H21: =IF(Inventory!A19="","",IF(ISNUMBER(SEARCH($C$2,Inventory!A19)),ROW(Inventory!A19),""))
